[2024-04-30T16:15:29.189+0200] {task_context_logger.py:104} ERROR - Executor reports task instance <TaskInstance: my_first_dag.task1 manual__2024-04-30T14:15:26.219393+00:00 [queued]> finished (failed) although the task says it's queued. (Info: None) Was the task killed externally?
